Workbook

Sheet Start here
A2: Sadaf Medical: data needed for useful reports
A4: A report-led input plan for Basic and Advanced. All submissions are weekly or monthly.
A7: Topic | B7: How to use this workbook
A8: Basic version | B8: Use ERP E01–E07, Basic weekly and Basic monthly. BW2 and BM2 are gap-only inputs; targets are optional for actuals reporting.
A9: Advanced version | B9: Use all Basic data plus E08–E09 and the Advanced tabs. E10–E13 can replace manual operational records when those exports exist.
A10: Weekly pack | B10: Refresh dated sales, receipts, unpaid balances and stock. Review BW1/BW2. Advanced also reviews AW1/AW2 and delivery exports.
A11: Monthly pack | B11: Close the previous month, reconcile to Alpha, confirm targets/settings, and review equipment, customer usage, costs and department results.
A12: Keep the work small | B12: Update existing records and unchanged settings only where needed. Fill a manual field only when it cannot be supplied reliably by an existing system.
A13: First monthly cycle | B13: Confirm ERP availability in the last two columns of ERP requirements. Load the historical baseline and current equipment/agreements in one starting pack.
A14: Required by the report | B14: Report map shows the exact ERP and manual inputs for every insight. Missing data leaves that insight unavailable; it must not become a guessed number.
A15: Colors and examples | B15: Blue rows are demo examples. Clear their contents before real use. Yellow cells are manual inputs; grey cells are conditional inputs or calculated outputs.
A16: Dates and units | B16: Keep original transaction, due, installation and expiry dates even though submission is weekly/monthly. Amounts are JOD; normalize pack sizes before comparing quantities.
A17: Prevent duplicates | B17: Transactions need stable IDs. Replace dated balance/stock snapshots rather than adding them together. Extra costs must not duplicate Alpha or product cost.
A18: Weekly / monthly alignment | B18: Use the latest complete month for activity, capacity and purchase-gap comparisons. Label its month on the weekly dashboard; do not compare a weekly purchase total with monthly demand.
... A26: Accounts update (v6) | B26: New sheet 'Accounts' (AM6 account master, AM7 targets and last year, AW3 tender detail, AM8 tender results) feeds the Tender accounts and Private accounts views under Sales and accounts. Worked examples rows 95 onward show every new calculation. ERP requirements E02, E03 and E05 gained fields.
A28: Basic ERP datasets confirmed | B28: =COUNTIF('ERP requirements'!G9:G15,"Available") -> 0
A29: Basic ERP datasets to verify | B29: =7-B28 -> 7
A30: Advanced accounting datasets confirmed | B30: =COUNTIF('ERP requirements'!G16:G17,"Available") -> 0
A31: Advanced accounting datasets to verify | B31: =2-B30 -> 2
A33: Available means all listed fields are verified in an export. Partial, Other system and manual completion still need a field-level check.
A34: These counts track export verification only. They do not certify report accuracy, integration or manual-data completion.

Sheet Report map
A2: Data required for each insight
A4: Each row states the minimum source data, the manual addition and what must remain unavailable when data is missing.
A5: Weekly reporting uses the latest dated ERP snapshot. Monthly equipment and department measures use the latest completed month, clearly labelled.
A8: Report ID | B8: Version | C8: Insight / report | D8: ERP inputs | E8: Manual inputs | F8: Report refresh | G8: Calculation / interpretation | H8: If required data is missing
A9: B01 | B9: Both | C9: Sales, gross profit and business mix | D9: E01 + E02 + E03 | E9: BM2 only for missing category/unit links | F9: Weekly | G9: Net sales less product cost; gross margin = gross profit / sales. Returns use the agreed sign convention. | H9: Without product costs, show sales only; margin is unavailable.
A10: B02 | B10: Both | C10: Cash collected and overdue balances | D10: E02 + E04 + E05 | E10: BW1: promised amounts/dates, owner and next action | F10: Weekly | G10: Sum receipts by receipt date. Age remaining invoices from contractual due date at the snapshot date. | H10: No receipts = no cash-collected figure. Unallocated cash stays separate; no cash/revenue conversion ratio.
A11: B03 | B11: Both | C11: Stock value by product and batch | D11: E01 + E06 | E11: BW2 only for missing batch/location/quantity fields | F11: Weekly | G11: Owned stock quantity x unit cost at one snapshot date. Use one counting unit. | H11: Missing batch or cost prevents the corresponding batch value; do not add snapshots together.
A12: B04 | B12: Both | C12: Expiry, slow stock and reorder flags | D12: E01 + E06 + E07 | E12: BW2: missing expiry; BM2: lead time, safety buffer and alert rules | F12: Weekly | G12: Stock days = quantity / daily issues. Forecast expiry by allocating demand to earliest-expiring batches first. | H12: No expiry = no expiry estimate. No demand baseline = stock value only. Loss estimates and slow stock overlap.
A13: B05 | B13: Both | C13: Management actions and promises | D13: E02 + E05 for customer and balance links | E13: BW1: action, owner, due date, status and promise details | F13: Weekly | G13: Open actions and due dates; confirm promised receipts in E04 before marking a collection complete. | H13: An action marked complete does not establish recovered sales or savings.
A14: B06 | B14: Both | C14: Targets versus results (useful addition) | D14: E01 + E03 + E04 | E14: BM1: category/company sales, margin and cash targets | F14: Monthly | G14: Compare the same month and category. Do not combine an All-company target with its category targets. | H14: Targets are optional. This comparison is a proposed addition, not a live calculation in the current demo.
A15: A01 | B15: Advanced | C15: Profit after delivery / project costs | D15: E03 + E09; E01 for category | E15: AM4: only missing costs or assignments | F15: Monthly | G15: Net sales - product cost - assigned actual direct costs not already in product cost. Estimates remain separate. | H15: Incomplete costs mean incomplete contribution. This is not company net profit or a cash forecast.
A16: A02 | B16: Advanced | C16: Tender stages, deadlines and planned profit | D16: E10 when available; E03/E05 once invoiced | E16: AW1: scope, stage, value, full cost estimate and next event | F16: Weekly | G16: Planned profit = tender value - full planned direct cost. Weighted margin = total planned profit / total value. | H16: A won tender is not recorded revenue. Missing full cost means planned profit is unavailable.
A17: A03 | B17: Advanced | C17: Installed units, warranties and agreements | D17: E01 + E02 + E11 when available | E17: AM1: unit status, installation, warranty and agreement dates | F17: Monthly | G17: Count active units once. Coverage includes contracts active at report date, including those due for renewal. | H17: Unknown contract status is not No contract. Missing installation date prevents an age-review flag.
A18: A04 | B18: Advanced | C18: Repeat consumable purchases and purchasing gap | D18: E03 + E01 + E02 | E18: AM1 + AM2 + AM3: unit links, approved usage rule, activity, stock and source | F18: Monthly | G18: Estimated quantity = activity x consumables/activity. Compare purchases in the same period, unit and price basis. | H18: Allocate each sale once. Without unit attribution, report customer totals or clearly labelled allocations; retain unclassified sales.
A19: A05 | B19: Advanced | C19: Equipment-use rate | D19: E11 if measured in an operating system | E19: AM3: activity count and practical capacity in the same unit; AM2 activity definition | F19: Monthly | G19: Equipment use = actual activity / practical capacity for the same month. Count each unit once if it uses several consumables. | H19: No denominator = no utilization %. Equipment use is not uptime.
... A27: A11 | B27: Advanced | C27: Tender status board, billing, guarantees and win rate | D27: E10 when available; E03/E05 once invoiced | E27: AW1 + AW3 + AM8 | F27: Weekly | G27: Pipeline = value of tenders Preparing or Submitted. Backlog = value x (1 - delivered %). Delivered not invoiced = value x delivered % - invoiced. Invoiced not collected = invoiced - collected (must equal the open E05 balance of that tender). Win rate = won / (won + lost). Guarantee days = expiry - snapshot date. | H27: A won tender is not revenue. Without delivered % the backlog is unavailable. Without AM8 or closed tenders in AW1 the win rate is unavailable.

Sheet ERP requirements
A2: What Alpha ERP should provide
A4: The accountant checks actual export availability. These are required business fields, not verified native Alpha column names.
A5: Edit only the last two columns. E01–E07 support Basic; E08–E09 add Advanced accounting data. E10–E13 are optional import routes.
A8: ID | B8: Version | C8: Data file / report | D8: Minimum fields needed | E8: Refresh | F8: Responsible role | G8: Availability | H8: Alpha report name / missing fields
A9: E01 | B9: Both | C9: Product and supplier list | D9: Product code; product name; category (Equipment / Devices / Consumables); therapeutic area (optional, for example Respiratory or Critical care; used by the portfolio-growth view); manufacturer; supplier code/name; counting unit; pack conversion; expiry tracked Yes/No. | E9: Monthly | F9: Accountant + product manager | G9: Not checked
A10: E02 | B10: Both | C10: Customer list | D10: Customer code/name; city; customer type; payment terms; account owner. Stable codes must match invoices and equipment. Add: customer segment or category that identifies public-sector tender customers; credit limit. | E10: Monthly | F10: Accountant + sales manager | G10: Not checked
A11: E03 | B11: Both | C11: Sales and returns | D11: Invoice and line IDs; date/type; customer; product; signed quantity, net sales and product cost JOD excluding tax. Project/order link is required for project profit; unit link when available. Keep returns/credits. Also export the same lines for the same months of the previous year (growth against last year). Add the contractual due date of each invoice where the ERP has it: it is needed to measure how late each customer pays, and E05 carries it only while the invoice is unpaid. | E11: Weekly | F11: Accountant | G11: Not checked
A12: E04 | B12: Both | C12: Customer receipts | D12: Receipt ID; allocation row ID; receipt date; customer; invoice/line link where available; allocated JOD. Include unapplied cash once. Allocation rows must add to the receipt total. Link each allocation to its invoice wherever possible: without the link, payment lateness cannot be measured. | E12: Weekly | F12: Accountant | G12: Not checked
A13: E05 | B13: Both | C13: Unpaid invoices | D13: Snapshot date; invoice ID; customer; invoice date; contractual due date; remaining amount JOD; account owner. Replace a snapshot, do not add successive balances. Keep the contractual due date for tender invoices; payment terms of 90 days or more are normal for public bodies. | E13: Weekly | F13: Accountant | G13: Not checked
A14: E06 | B14: Both | C14: Stock by batch | D14: Snapshot date; product; warehouse; batch; quantity; counting unit; unit cost; expiry date; ownership. Exclude or separately value stock not owned by Sadaf. | E14: Weekly | F14: Warehouse + accountant | G14: Not checked
A15: E07 | B15: Both | C15: Stock transaction history | D15: Unique transaction ID; date; product/batch/warehouse; transaction type; signed quantity; counting unit. Separate customer issues, returns, transfers and adjustments. | E15: Weekly | F15: Warehouse + accountant | G15: Not checked
A16: E08 | B16: Advanced | C16: Supplier and customer deliveries | D16: Delivery/PO line ID; inbound/outbound; supplier/customer; product/category; promised completion date; actual full completion date; outstanding quantity; status; snapshot date. Keep overdue open deliveries. | E16: Weekly | F16: Purchasing + logistics | G16: Not checked
A17: E09 | B17: Advanced | C17: Direct project costs | D17: Unique cost line/reference; date; project/order; product category; cost type; amount JOD; Actual or Estimate; whether already included in product cost. Identify urgent freight. | E17: Monthly | F17: Accountant | G17: Not checked
A18: E10 | B18: Advanced | C18: Quotes / tenders if recorded | D18: Optional ERP/CRM route: supply the same fields as AW1. If unavailable, the commercial team maintains AW1 manually. | E18: Weekly | F18: Sales + tender team | G18: Not checked
A19: E11 | B19: Advanced | C19: Equipment / agreements if recorded | D19: Optional ERP/service-system route: supply the AM1 unit, installation, warranty and agreement fields. Otherwise maintain AM1 manually. | E19: Monthly | F19: Service manager | G19: Not checked
A20: E12 | B20: Advanced | C20: Support cases if recorded | D20: Optional route: case ID; opened/first response/closed times; response-time target; calendar or business-hour rule. Calculate AM5 counts from the source instead of retyping them. | E20: Monthly | F20: Service manager | G20: Not checked
A21: E13 | B21: Advanced | C21: HR / document checks if recorded | D21: Optional route: critical vacancy opened/filled dates and critical flag; tender review ID/date and complete-at-first-review result. Otherwise submit confirmed monthly AM5 totals. | E21: Monthly | F21: HR + tender manager | G21: Not checked
A24: Partial or Unavailable: identify the exact missing fields. Use a manual table only for those gaps. Do not recreate the entire ERP dataset.
A25: Receipt totals are essential for cash collected. Invoice totals and unpaid balances cannot replace a receipts ledger.
A26: Category-level cash requires invoice-line allocation or an agreed allocation rule. Show unallocated cash separately.
A27: First monthly cycle: retain current-year history and at least three complete months of stock issues for a simple demand baseline.
A28: Weekly updates keep original transaction dates and unique IDs. Monthly review reconciles sales, costs, cash, balances and stock to Alpha.
A29: E08 fallback: use AW2 for every delivery due in the month when the ERP list is absent. A list of delays alone cannot give an on-time percentage.

Sheet Imports and predictions
A2: Importing data and the estimate features (v7)
A4: How the app loads the Alpha exports, and the data the new estimate features need.
A5: Header names are assumptions until a real Alpha export is checked. Estimates are labelled ESTIMATED and are never shown as facts.
A7: 1. How importing works
A8: Topic | B8: Rule
A9: Who and where | B9: The company owner uploads CSV files on the Import data page of the app: UTF-8, one file per type, up to 4.5 MB. Split large sales exports by month. In Excel use Save As, CSV UTF-8.
A10: Order | B10: Import E01 products and E02 customers first, then E03 sales, E04 receipts, E05 unpaid invoices, E06 stock, E07 stock transactions and installed equipment. Later files point at product and customer codes that must already exist. A row with an unknown code is rejected; it is never created.
A11: Check first | B11: Use Check file before Import. It validates every row and shows totals (net sales, cash received, outstanding by age, stock value) to compare with Alpha, and saves nothing.
A12: No double counting | B12: The same file cannot be imported twice. A changed file updates rows by their ERP IDs (invoice + line, receipt + allocation row, transaction ID, product / customer / unit codes); it never duplicates them.
A13: Snapshot files | B13: Unpaid invoices (E05) and stock by batch (E06) are point-in-time. A file for a date replaces that date; other dates are kept and never added together. The file needs a snapshot date column, or the date is entered when uploading.
A14: Bad rows | B14: Good rows are saved and bad rows are listed with the row number and the reason (status Partial). Fix them in the file and import it again.
A15: Unknown stays unknown | B15: A blank due date, cost, segment, credit limit or payment term is kept as unknown, never as 0 or a default segment. An unrecognised customer segment is left unclassified with a warning. Public / government / tender wording is read as Tender.
A16: Dates and numbers | B16: Dates as YYYY-MM-DD or day-first D/M/YYYY; month-first dates are not supported. Dates after the import day are rejected. Amounts are JOD with a decimal point; returns are negative; thousands separators are accepted. Arabic text and Arabic digits are accepted.
A17: Receipts | B17: If the file has a receipt total column, the allocation rows of a receipt must add up to it. An allocation to an invoice that is not in the imported invoices is kept once, as not linked to an invoice, with a warning.
A18: Column names | B18: The header names below are assumptions, not Alpha's real column names. Matching ignores case, spaces and punctuation and accepts common alternatives. They are adjusted once a real Alpha export is checked.
A20: 2. Columns the importer reads (first name shown; other spellings are accepted)
A21: File type | B21: Required columns | C21: Optional columns | D21: Point in time?
A22: Product and supplier list (E01) | B22: product code, product name, category | C22: therapeutic area, manufacturer, supplier code, supplier name, unit, pack conversion, expiry tracked, active | D22: No
A23: Customer list (E02) | B23: customer code, customer name | C23: city, customer type, segment, payment terms, credit limit, account owner, active | D23: No
A24: Sales and returns (E03) | B24: invoice no, line no, invoice date, customer code, product code, quantity, net sales | C24: due date, doc type, product cost, project, account owner | D24: No
A25: Customer receipts (E04) | B25: receipt no, allocation row id, receipt date, customer code, allocated amount | C25: invoice no, receipt total | D25: No
A26: Unpaid invoices (E05) | B26: invoice no, customer code, invoice date, remaining amount | C26: snapshot date, due date, account owner | D26: Yes: needs a snapshot date (column or upload form)
A27: Stock by batch (E06) | B27: product code, warehouse, quantity | C27: snapshot date, batch, unit cost, expiry date, owned | D27: Yes: needs a snapshot date (column or upload form)
A28: Stock transactions (E07) | B28: transaction id, transaction date, product code, warehouse, transaction type, quantity | C28: batch | D28: No
A29: Installed equipment (E11 or manual) | B29: unit code, customer code, unit name | C29: product code, installed on, warranty end, service, expected monthly consumables | D29: No
A31: 3. Estimate features (built, tested and shown on the Management actions screen; each is labelled ESTIMATED)
A32: Feature | B32: Question it answers | C32: Data needed | D32: Minimum history | E32: Shown as | F32: If data is missing
A33: Repurchase timing | B33: Which customers are due, overdue or lapsed on reordering? | C33: E03 order dates per customer. | D33: At least 4 distinct order dates per customer. | E33: ESTIMATED. Typical days between orders (median), expected next order date, level On cycle / Due soon / Overdue / Lapsed, and confidence Higher or Lower when the intervals vary a lot. | F33: 'Not enough data'. Nothing is guessed. An order dated after the report date is treated as a bad import.
A34: Payment behaviour | B34: How late does each customer usually pay? | C34: Invoice due date (E03 due date or E05) and payment date (E04 receipt allocated to that invoice). | D34: At least 5 paid invoices per customer. | E34: ESTIMATED. Typical days late (median), a cautious figure that 80% of invoices stay within, and the share of invoices paid late. | F34: 'Not enough data'. Invoices without a due date or without an invoice link on the receipt do not count.
A35: Cash forecast | B35: How much cash is likely in the next 30 / 60 / 90 days? | C35: E05 unpaid invoices plus each customer's payment behaviour. | D35: Customers with enough payment history (see above). | E35: ESTIMATED. Expected collections per window. Invoices already past their customer's typical payment day, invoices of customers without history, and invoices expected after 90 days are shown separately. | F35: Money that cannot be forecast is listed, not guessed. The parts always add up to the total outstanding.
A36: Opportunity ranking | B36: Which customers should the team call first? | C36: The signals above (for example overdue repurchase) and the consumables purchase gap, each with an estimated JOD value. | D36: Not applicable. | E36: ESTIMATED. One line per customer showing the largest signal; other signals on the same customer are named but not added. | F36: Only signals with a positive value are ranked. The total is not the sum of overlapping signals.
A38: 4. History to load before the first use
A39: Minimum to start | B39: Load all available history, ideally 12 months: E03 sales with order dates and due dates, and E04 receipts linked to their invoices. Then keep adding E03, E04 and E05 weekly. A customer who orders monthly needs about 4 months of orders and 5 paid invoices before an estimate appears; until then the feature says 'Not enough data'.

Sheet Basic weekly
A2: Basic: weekly manual inputs
A4: One weekly review. Enter only new or changed records and any fields missing from Alpha.
A5: Blue rows are fictional examples; clear them before real use. Yellow = manual entry. Grey = conditional fields.
A7: BW1. Actions and payment promises
A8: MANUAL. One row per action code. Update the same row weekly. Promise amount/date are used only for collection promises.
A9: Updated by: Accountant / sales owner. Review weekly; carry forward unchanged records.
A10: Review week ending | B10: Action code | C10: Customer / product / order code | D10: Next action | E10: Responsible person | F10: Action due date | G10: Status | H10: Promised amount (JOD) | I10: Promised payment date
A11: 46303 | B11: DEMO-ACT-A | C11: DEMO-C001 | D11: Confirm promised payment against DEMO-T-A | E11: Demo Ahmad | F11: 46309 | G11: Open | H11: 7200 | I11: 46310
A12: 46303 | B12: DEMO-ACT-B | C12: DEMO-C002 | D12: Review circuit usage and next order | E12: Demo Lina | F12: 46304 | G12: In progress
A20: BW2. Missing stock and expiry fields
A21: MANUAL ONLY IF E06 IS INCOMPLETE. Match product + batch + location. Quantity is entered only when the batch quantity is missing.
A22: Updated by: Warehouse team. Review weekly; carry forward unchanged records.
A23: Week ending | B23: Product code | C23: Batch code | D23: Warehouse / location | E23: Batch quantity if missing | F23: Counting unit | G23: Expiry date | H23: Source / check reference
A24: 46303 | B24: DEMO-MED-ST10 | C24: DEMO-LOT-A | D24: Amman demo warehouse | E24: 600 | F24: piece | G24: 46752 | H24: DEMO-BATCH-A
A25: 46303 | B25: DEMO-VAP-HIGH | C25: DEMO-LOT-B | D25: Amman demo warehouse | E25: 80 | F25: piece | G25: 46371 | H25: DEMO-BATCH-B

Sheet Basic monthly
A2: Basic: monthly manual inputs
A4: Confirm targets and missing reference details once a month. Stable settings are carried forward; do not retype them.
A5: Blue = demo examples. Only missing fields go here; the product/customer lists remain in Alpha.
A7: BM1. Monthly targets
A8: MANUAL MANAGEMENT PLAN. Optional for actuals-only reporting. Choose company-wide or category targets for a month, not both.
A9: Updated by: Management / finance. Review monthly; carry forward unchanged records.
A10: Month | B10: Category or All | C10: Sales target (JOD) | D10: Gross margin target | E10: Collection target (JOD)
A11: 46266 | B11: Equipment | C11: 26000 | D11: 0.25 | E11: 17000
A12: 46266 | B12: Devices | C12: 32000 | D12: 0.3 | E12: 22000
A20: BM2. Missing master fields and report assumptions
A21: MANUAL / GAP ONLY. One row per scope + field. Use All for company policy or an exact product/unit/customer code for a specific setting.
A22: Updated by: Product manager / finance. Review monthly; carry forward unchanged records.
A23: Reviewed month | B23: Scope / record code | C23: Field to maintain | D23: Confirmed value | E23: Source / approval reference
A24: 46266 | B24: DEMO-MED-ST10 | C24: Lead time days | D24: 14 | E24: DEMO supplier lead-time confirmation
A25: 46266 | B25: All | C25: Expiry warning days | D25: 90 | E25: DEMO management stock policy
A36: Required for the relevant insight: category/unit mapping; lead time and stock rules; renewal/age rules; recovery-share and margin assumptions.
A37: Percentage settings in BM2 use whole percentages, e.g. 40 means 40%. BM1 gross margin uses Excel percentage format, e.g. 25%.
A38: For stock with no consumption, show No recent use. Do not divide by zero or assume the stock is a confirmed loss.

Sheet Advanced weekly
A2: Advanced: weekly manual inputs
A4: Use Basic weekly too. Import the same operational data from Alpha/CRM when available; otherwise use these two registers.
A5: One weekly snapshot of open work. Retain original event dates. Blue rows are fictional examples.
A7: AW1. Quotes, tenders and next deadlines
A8: MANUAL IF E10 IS UNAVAILABLE. One total row per tender/quote. Mixed categories use Mixed; never repeat the full tender value for each product.
A9: Updated by: Sales / tender lead. Review weekly; carry forward unchanged records.
A10: Record code | B10: Record type | C10: Customer code | D10: Category | E10: Product / scope | F10: Stage | G10: Total value (JOD) | H10: Full planned cost (JOD) | I10: Next event / key issue | J10: Next event date | K10: Responsible person
A11: DEMO-T-A | B11: Tender | C11: DEMO-C001 | D11: Equipment | E11: 10 MEDIMA P300 pumps | F11: Delivered | G11: 24000 | H11: 18600 | I11: Collect promised balance | J11: 46310 | K11: Demo Ahmad
A12: DEMO-T-B | B12: Tender | C12: DEMO-C002 | D12: Devices | E12: 2 Vapotherm Precision Flow systems | F12: Delivered | G12: 30000 | H12: 21900 | I12: Collect final balance | J12: 46315 | K12: Demo Lina
A20: AW2. Delivery records missing from Alpha
A21: MANUAL ONLY FOR E08 GAPS. If there is no ERP delivery list, include ALL deliveries due, not just late ones. Actual date is blank until fully completed.
A22: Updated by: Purchasing / logistics. Review weekly; carry forward unchanged records.
A23: Week ending | B23: Delivery / PO line code | C23: Direction | D23: Supplier / customer code | E23: Promised full-delivery date | F23: Actual full-delivery date | G23: Outstanding quantity | H23: Delay cause / source
A24: 46303 | B24: DEMO-DEL-A | C24: Outbound | D24: DEMO-C001 | E24: 46284 | F24: 46285 | G24: 0 | H24: One day late; DEMO delivery note A
A25: 46303 | B25: DEMO-DEL-B | C25: Outbound | D25: DEMO-C002 | E25: 46287 | F25: 46287 | G25: 0 | H25: On time; DEMO delivery note B
A33: Full planned cost includes product purchasing, freight, installation, training and expected warranty cost. Leave it blank until that estimate is complete.
A34: A deadline can fall between weekly submissions. The report shows the last submitted state and is not a live operational alert service.

Sheet Advanced monthly
A2: Advanced: monthly manual inputs
A4: Use Basic monthly too. Update stable equipment/rule records only where they changed; enter monthly activity and confirmed results.
A5: Do not enter rows already supplied by an ERP, service or HR export. Blue rows are illustrative; all commercial figures and customer records are fictional.
A7: AM1. Installed equipment and agreements
A8: MANUAL IF E11 IS UNAVAILABLE. One row per physical unit. Confirm No contract explicitly; blank dates do not prove there is no agreement.
A9: Updated by: Service team. Review monthly; carry forward unchanged records.
A10: Unit / serial ID | B10: Customer code | C10: Model product code | D10: Installation date | E10: Unit status | F10: Ownership | G10: Warranty ends | H10: Agreement held? | I10: Agreement starts | J10: Agreement ends | K10: Agreement reference
A11: DEMO-EQ-A | B11: DEMO-C001 | C11: DEMO-MED-P300 | D11: 45809 | E11: Active | F11: Customer-owned | G11: 46173 | H11: Yes | I11: 46174 | J11: 46538 | K11: DEMO-SC-A
A12: DEMO-EQ-B | B12: DEMO-C002 | C12: DEMO-VAP-PF | D12: 44089 | E12: Active | F12: Customer-owned | G12: 45914 | H12: No
A20: AM2. Approved consumable and activity rules
A21: TECHNICAL / MANUAL. Confirm suitability and units from approved evidence. Demo pairings and quantities are not technical or clinical instructions.
A22: Updated by: Service / technical team. Review monthly; carry forward unchanged records.
A23: Model product code | B23: Consumable product code | C23: Activity counting unit | D23: Consumable quantity per activity | E23: Consumable counting unit | F23: Technical evidence reference | G23: Last checked
A24: DEMO-MED-P300 | B24: DEMO-MED-ST10 | C24: Procedure | D24: 1 | E24: piece | F24: DEMO assumption; verify approved setup | G24: 46295
A25: DEMO-VAP-PF | B25: DEMO-VAP-HIGH | C25: Treatment | D25: 1 | E25: piece | F25: DEMO assumption; verify approved setup | G25: 46295
A33: AM3. Monthly equipment use and customer stock
A34: MANUAL CUSTOMER / OPERATING DATA. Activity and capacity use the same unit. Price and sales allocation are conditional; see the notes below.
A35: Updated by: Account owner with customer. Review monthly; carry forward unchanged records.
A36: Month | B36: Unit ID | C36: Consumable product code | D36: Activity count | E36: Practical activity capacity | F36: Customer-held quantity | G36: Price JOD if unavailable | H36: Sales allocation % if needed | I36: Evidence / reliability
A37: 46266 | B37: DEMO-EQ-A | C37: DEMO-MED-ST10 | D37: 120 | E37: 160 | F37: 16 | I37: DEMO activity log; customer confirmed
A38: 46266 | B38: DEMO-EQ-B | C38: DEMO-VAP-HIGH | D38: 24 | E38: 30 | F38: 6 | I38: DEMO customer estimate; verify
A46: AM4. Project costs or assignments missing from Alpha
A47: MANUAL ONLY FOR E09 GAPS. Match a unique cost reference before combining with Alpha. Enter Actual and Estimate separately.
A48: Updated by: Accountant. Review monthly; carry forward unchanged records.
A49: Cost reference | B49: Cost date | C49: Project / order code | D49: Category | E49: Cost type | F49: Actual or Estimate | G49: Amount (JOD) | H49: Source / assignment basis
A50: DEMO-COST-A | B50: 46285 | C50: DEMO-T-A | D50: Equipment | E50: Freight | F50: Actual | G50: 600 | H50: DEMO invoice A; excluded from ERP product cost
A51: DEMO-COST-B | B51: 46287 | C51: DEMO-T-B | D51: Devices | E51: Installation | F51: Actual | G51: 900 | H51: DEMO work note B; excluded from ERP product cost
A59: AM5. Monthly department results
A60: COUNTS MANUAL IF E12/E13 ARE UNAVAILABLE. Management confirms targets. Ratios need both counts; report figures are calculated.
A61: Updated by: Service / tender / HR lead. Review monthly; carry forward unchanged records.
A62: Month | B62: Indicator | C62: Count meeting target / vacancy days | D62: Total checked for a rate | E62: Target (% or days) | F62: Evidence reference | G62: Calculated result (% or days)
A63: 46266 | B63: Support responses on time | C63: 42 | D63: 50 | E63: 95 | F63: DEMO cases opened in September | G63: =IF(B63="","",IF(OR(B63="Oldest critical vacancy days",B63="Open support cases"),IF(ISNUMBER(C63),C63,"Data missing"),IF(AND(ISNUMBER(C63),ISNUMBER(D63),D63>0),IF(C63<=D63,C63/D63*100,"Check counts"),"Data missing"))) -> 84
A64: 46266 | B64: Documents complete at first review | C64: 19 | D64: 25 | E64: 98 | F64: DEMO September first-review log | G64: =IF(B64="","",IF(OR(B64="Oldest critical vacancy days",B64="Open support cases"),IF(ISNUMBER(C64),C64,"Data missing"),IF(AND(ISNUMBER(C64),ISNUMBER(D64),D64>0),IF(C64<=D64,C64/D64*100,"Check counts"),"Data missing"))) -> 76
G65: =IF(B65="","",IF(OR(B65="Oldest critical vacancy days",B65="Open support cases"),IF(ISNUMBER(C65),C65,"Data missing"),IF(AND(ISNUMBER(C65),ISNUMBER(D65),D65>0),IF(C65<=D65,C65/D65*100,"Check counts"),"Data missing")))
G66: =IF(B66="","",IF(OR(B66="Oldest critical vacancy days",B66="Open support cases"),IF(ISNUMBER(C66),C66,"Data missing"),IF(AND(ISNUMBER(C66),ISNUMBER(D66),D66>0),IF(C66<=D66,C66/D66*100,"Check counts"),"Data missing")))
G67: =IF(B67="","",IF(OR(B67="Oldest critical vacancy days",B67="Open support cases"),IF(ISNUMBER(C67),C67,"Data missing"),IF(AND(ISNUMBER(C67),ISNUMBER(D67),D67>0),IF(C67<=D67,C67/D67*100,"Check counts"),"Data missing")))
G68: =IF(B68="","",IF(OR(B68="Oldest critical vacancy days",B68="Open support cases"),IF(ISNUMBER(C68),C68,"Data missing"),IF(AND(ISNUMBER(C68),ISNUMBER(D68),D68>0),IF(C68<=D68,C68/D68*100,"Check counts"),"Data missing")))
A72: AM3 price: use a matching customer/product price from Alpha first. If missing, enter a confirmed quote price and its evidence.
A73: AM3 allocation: use direct unit links first. If one customer/product serves several units, use confirmed shares totalling 100% or an approved rule.
A74: Never attach the full customer purchase amount to every unit. Unallocated purchases stay at customer level. Repeat activity/capacity consistently per unit.
...

Sheet Accounts
A2: Accounts and tenders: manual inputs
A4: Splits Sadaf's customers into Tender accounts (public-sector bodies that buy through formal tenders) and Private accounts (private hospitals, centres and clinics that buy by quotation or purchase order).
A5: Fill only what Alpha ERP cannot supply. Blue rows are fictional examples: clear them before real use. Yellow cells are manual inputs. Dates are dd-mmm-yyyy.
A7: AM6. Account master: segment, terms and credit limit
A8: MANUAL IF E02 DOES NOT CARRY THEM. One row per customer code. Segment decides which view the account appears in; it never changes sales figures, only grouping.
A9: Updated by: Sales manager + accountant. Review monthly; update a row only when terms, limit or segment change.
A10: Customer code | B10: Customer name | C10: Segment | D10: Customer type | E10: City | F10: Account owner | G10: Payment terms (days) | H10: Credit limit (JOD) | I10: Active?
A11: DEMO-C001 | B11: Demo Hospital A | C11: Tender | D11: Public hospital | E11: Amman | F11: Demo Ahmad | G11: 90 | H11: 40000 | I11: Yes
A12: DEMO-C002 | B12: Demo Hospital B | C12: Tender | D12: Public hospital | E12: Irbid | F12: Demo Lina | G12: 90 | H12: 50000 | I12: Yes
A13: DEMO-C003 | B13: Demo Clinic C | C13: Private | D13: Specialist clinic | E13: Amman | F13: Demo Omar | G13: 45 | H13: 10000 | I13: Yes
A44: AM7. Account targets and last year's figures
A45: MANUAL. One row per customer and month, figures YEAR TO DATE up to that month. Prior-year columns can be skipped when Alpha ERP history (E03) is loaded for the same period last year.
A46: Updated by: Management / finance. Review monthly; replace the month's rows, do not add successive months together.
A47: Year to date at month | B47: Customer code | C47: Sales target (JOD) | D47: Prior-year sales, same period (JOD) | E47: Prior-year gross profit, same period (JOD) | F47: Source / approval reference
A48: 46266 | B48: DEMO-C001 | C48: 110000 | D48: 100000 | E48: 22000 | F48: DEMO management plan; ERP history
A49: 46266 | B49: DEMO-C002 | C49: 90000 | D49: 85000 | E49: 20000 | F49: DEMO management plan; ERP history
A50: 46266 | B50: DEMO-C003 | C50: 65000 | D50: 66000 | E50: 25000 | F50: DEMO management plan; ERP history
A81: AW3. Tender detail: award, delivery, billing and guarantees
A82: MANUAL, ADDS TO AW1. One row per tender record code already in AW1 (the stage, value, full planned cost and next event stay in AW1). Replace the row weekly while the tender is live.
A83: Updated by: Tender department + accountant. Review weekly; keep closed tenders until the year ends so results can be counted.
A84: Record code (from AW1) | B84: Authority tender number | C84: Award date | D84: Delivered (%) | E84: Invoiced to date (JOD) | F84: Collected to date (JOD) | G84: Guarantee type | H84: Guarantee amount (JOD) | I84: Guarantee expiry | J84: Outcome / loss reason
A85: DEMO-T-A | B85: DEMO-AUTH-001 | C85: 46218 | D85: 100 | E85: 24000 | F85: 16800 | G85: Performance bond | H85: 2400 | I85: 46366 | J85: Won
A86: DEMO-T-B | B86: DEMO-AUTH-002 | C86: 46233 | D86: 100 | E86: 30000 | F86: 21000 | G86: Performance bond | H86: 3000 | I86: 46446 | J86: Won
A118: AM8. Tender results this year
A119: MANUAL, ONLY IF AW1 DOES NOT KEEP EVERY CLOSED TENDER. Cumulative counts and values from 1 January to the month shown. Pending means submitted with no decision yet.
A120: Updated by: Tender department. Review monthly; replace the single row for the month.
A121: Year to date at month | B121: Tenders submitted | C121: Won | D121: Lost | E121: Pending | F121: Value submitted (JOD) | G121: Value won (JOD) | H121: Counts check
A122: 46266 | B122: 14 | C122: 6 | D122: 5 | E122: 3 | F122: 3900000 | G122: 1650000 | H122: =IF(B122="","",IF(B122=C122+D122+E122,"OK","Counts do not add up")) -> OK
H123: =IF(B123="","",IF(B123=C123+D123+E123,"OK","Counts do not add up"))
H124: =IF(B124="","",IF(B124=C124+D124+E124,"OK","Counts do not add up"))
H125: =IF(B125="","",IF(B125=C125+D125+E125,"OK","Counts do not add up"))
H126: =IF(B126="","",IF(B126=C126+D126+E126,"OK","Counts do not add up"))
H127: =IF(B127="","",IF(B127=C127+D127+E127,"OK","Counts do not add up"))
A130: Tender account = public-sector body buying through formal tenders (ministries, university and government hospitals, military medical services, joint procurement). Private account = private hospital, centre or clinic buying by quotation or purchase order. Decide the segment once per customer and keep it stable.
A131: Orders, last order date, average order and sales by line come from the invoices in E03; do not type them here. Receivables and overdue come from E05; cash received from E04.
A132: Prior-year figures must cover the same months as the sales they are compared with (year to date against year to date), on the same net-of-tax basis.
A133: Guarantee amounts are held by the bank or the authority, not revenue or cost. Track expiry so a bond is never left to lapse during delivery or warranty.
A134: Win rate = won / (won + lost). Pending tenders are excluded until decided. Pipeline value is face value and is not weighted by invented probabilities.

Sheet Worked examples
A2: Worked examples: Basic and Advanced
A4: Fictional September 2026 records; balances and stock are checked at 08-Oct-2026. Each project and unit is matched by code.
A6: Measure | B6: Demo Hospital A | C6: Demo Hospital B | E6: Meaning / source
A7: Example ERP values (not manual inputs)
A8: Customer code | B8: DEMO-C001 | C8: DEMO-C002
A9: Project code | B9: DEMO-T-A | C9: DEMO-T-B
A10: Unit ID | B10: DEMO-EQ-A | C10: DEMO-EQ-B
A11: Model product code | B11: DEMO-MED-P300 | C11: DEMO-VAP-PF
A12: Consumable product code | B12: DEMO-MED-ST10 | C12: DEMO-VAP-HIGH
A13: Month start | B13: 46266 | C13: 46266
A14: Month end | B14: 46295 | C14: 46295
A15: Balance / stock snapshot | B15: 46303 | C15: 46303
A17: Project sales (JOD) | B17: 24000 | C17: 30000 | E17: E03. Two delivered equipment/device projects; these are not whole-company sales.
A18: Project product cost (JOD) | B18: 18000 | C18: 21000 | E18: E03. Excludes the additional freight/installation in AM4.
A19: Project receipts in September (JOD) | B19: 16800 | C19: 21000 | E19: E04. Receipts allocated to these projects in this example.
A20: Outstanding at snapshot (JOD) | B20: 7200 | C20: 9000 | E20: E05. Separate invoice balances; not estimated from current-month sales.
A21: Invoice contractual due date | B21: 46293 | C21: 46315 | E21: E05. The promised payment date in BW1 does not replace the contractual due date.
A22: Consumables purchased (pieces) | B22: 80 | C22: 12 | E22: E03. September net quantities. One unit per customer/product in these examples.
A23: Consumable sales (JOD) | B23: 240 | C23: 600 | E23: E03. Separate consumable transactions; counted once in Consumables.
A24: Consumable product cost (JOD) | B24: 144 | C24: 360 | E24: E03. For the same consumable transactions.
A25: Comparison price (JOD / piece) | B25: 3 | C25: 50 | E25: E03. One matching unit price for estimated demand and purchase comparison.
A26: Warehouse quantity (pieces) | B26: 600 | C26: 80 | E26: E06. Warehouse stock is different from stock held by a customer.
A27: Warehouse unit cost (JOD) | B27: 1.8 | C27: 30 | E27: E06. Same counting unit as quantity.
A28: Batch expiry date | B28: 46752 | C28: 46371 | E28: E06 or BW2. Single-batch illustration.
A29: Average daily issues (pieces) | B29: 5 | C29: 0.83333333 | E29: E07. Illustrative historical rates; transfers/adjustments are excluded.
A32: Illustrative management assumptions
A33: Share of gap that could be won | B33: 0.4 | E33: BM2 in a live pack. A scenario choice, not a probability inferred from the data.
A34: Extra-sales margin after direct costs | B34: 0.3 | E34: BM2. Assumed contribution margin, excluding overhead, tax and financing.
A35: Equipment age review threshold (years) | B35: 5 | E35: BM2. Review signal only, not a required replacement age.
A36: Agreement renewal warning (days) | B36: 30 | E36: BM2. Contracts within the warning window still count as covered until expiry.
A40: Basic report calculations
A41: Project sales (JOD) | B41: =B17 -> 24000 | C41: =C17 -> 30000
A42: Gross profit (JOD) | B42: =B17-B18 -> 6000 | C42: =C17-C18 -> 9000 | E42: Sales less product cost.
A43: Gross margin | B43: =IF(B17=0,"Data missing",B42/B17) -> 0.25 | C43: =IF(C17=0,"Data missing",C42/C17) -> 0.3
A44: Cash collected (JOD) | B44: =B19 -> 16800 | C44: =C19 -> 21000
A45: Remaining invoice balance (JOD) | B45: =B20 -> 7200 | C45: =C20 -> 9000
A46: Days overdue | B46: =IF(B20>0,MAX(0,B15-B21),0) -> 10 | C46: =IF(C20>0,MAX(0,C15-C21),0) -> 0 | E46: Days from contractual due date to snapshot; zero if not yet due.
A47: Overdue amount (JOD) | B47: =IF(B46>0,B20,0) -> 7200 | C47: =IF(C46>0,C20,0) -> 0
A48: Warehouse stock value (JOD) | B48: =B26*B27 -> 1080 | C48: =C26*C27 -> 2400
A49: Warehouse stock lasts (days) | B49: =IF(B29=0,"No recent use",B26/B29) -> 120 | C49: =IF(C29=0,"No recent use",C26/C29) -> 96
...
